[2024-04-09T20:08:23.773+0000] {task_context_logger.py:104} ERROR - Executor reports task instance <TaskInstance: fruits_dag.get_fruit_data scheduled__2023-04-02T00:00:00+00:00 [queued]> finished (failed) although the task says it's queued. (Info: None) Was the task killed externally?
