[2024-04-09T09:16:33.728+0000] {local_task_job_runner.py:120} INFO - ::group::Pre task execution logs
[2024-04-09T09:16:33.807+0000] {taskinstance.py:2073} INFO - Dependencies all met for dep_context=non-requeueable deps ti=<TaskInstance: dag_1.create_our_works_works_txt_file manual__2024-04-09T09:05:54.988182+00:00 [queued]>
[2024-04-09T09:16:33.847+0000] {taskinstance.py:2073} INFO - Dependencies all met for dep_context=requeueable deps ti=<TaskInstance: dag_1.create_our_works_works_txt_file manual__2024-04-09T09:05:54.988182+00:00 [queued]>
[2024-04-09T09:16:33.848+0000] {taskinstance.py:2303} INFO - Starting attempt 2 of 2
[2024-04-09T09:16:33.892+0000] {taskinstance.py:2327} INFO - Executing <Task(BashOperator): create_our_works_works_txt_file> on 2024-04-09 09:05:54.988182+00:00
[2024-04-09T09:16:33.913+0000] {warnings.py:110} WARNING - /home/***/.local/lib/python3.12/site-packages/***/task/task_runner/standard_task_runner.py:61: DeprecationWarning: This process (pid=1099) is multi-threaded, use of fork() may lead to deadlocks in the child.
  pid = os.fork()

[2024-04-09T09:16:33.916+0000] {standard_task_runner.py:63} INFO - Started process 1103 to run task
[2024-04-09T09:16:33.917+0000] {standard_task_runner.py:90} INFO - Running: ['***', 'tasks', 'run', 'dag_1', 'create_our_works_works_txt_file', 'manual__2024-04-09T09:05:54.988182+00:00', '--job-id', '19', '--raw', '--subdir', 'DAGS_FOLDER/dag-1.py', '--cfg-path', '/tmp/tmpbt98gz66']
[2024-04-09T09:16:33.926+0000] {standard_task_runner.py:91} INFO - Job 19: Subtask create_our_works_works_txt_file
[2024-04-09T09:16:34.045+0000] {task_command.py:426} INFO - Running <TaskInstance: dag_1.create_our_works_works_txt_file manual__2024-04-09T09:05:54.988182+00:00 [running]> on host b6bc23c6abe9
[2024-04-09T09:16:34.364+0000] {taskinstance.py:2644} INFO - Exporting env vars: AIRFLOW_CTX_DAG_OWNER='***' AIRFLOW_CTX_DAG_ID='dag_1' AIRFLOW_CTX_TASK_ID='create_our_works_works_txt_file' AIRFLOW_CTX_EXECUTION_DATE='2024-04-09T09:05:54.988182+00:00' AIRFLOW_CTX_TRY_NUMBER='2' AIRFLOW_CTX_DAG_RUN_ID='manual__2024-04-09T09:05:54.988182+00:00'
[2024-04-09T09:16:34.372+0000] {taskinstance.py:430} INFO - ::endgroup::
[2024-04-09T09:16:34.377+0000] {subprocess.py:63} INFO - Tmp dir root location: /tmp
[2024-04-09T09:16:34.380+0000] {subprocess.py:75} INFO - Running command: ['/usr/bin/bash', '-c', 'touch our_works/works.txt']
[2024-04-09T09:16:34.443+0000] {subprocess.py:86} INFO - Output:
[2024-04-09T09:16:34.458+0000] {subprocess.py:93} INFO - touch: cannot touch 'our_works/works.txt': No such file or directory
[2024-04-09T09:16:34.462+0000] {subprocess.py:97} INFO - Command exited with return code 1
[2024-04-09T09:16:34.467+0000] {taskinstance.py:441} INFO - ::group::Post task execution logs
[2024-04-09T09:16:34.551+0000] {taskinstance.py:2890} ERROR - Task failed with exception
Traceback (most recent call last):
  File "/home/airflow/.local/lib/python3.12/site-packages/airflow/models/taskinstance.py", line 465, in _execute_task
    result = _execute_callable(context=context, **execute_callable_kwargs)
             ^^^^^^^^^^^^^^^^^^^^^^^^^^^^^^^^^^^^^^^^^^^^^^^^^^^^^^^^^^^^^
  File "/home/airflow/.local/lib/python3.12/site-packages/airflow/models/taskinstance.py", line 432, in _execute_callable
    return execute_callable(context=context, **execute_callable_kwargs)
           ^^^^^^^^^^^^^^^^^^^^^^^^^^^^^^^^^^^^^^^^^^^^^^^^^^^^^^^^^^^^
  File "/home/airflow/.local/lib/python3.12/site-packages/airflow/models/baseoperator.py", line 400, in wrapper
    return func(self, *args, **kwargs)
           ^^^^^^^^^^^^^^^^^^^^^^^^^^^
  File "/home/airflow/.local/lib/python3.12/site-packages/airflow/operators/bash.py", line 243, in execute
    raise AirflowException(
airflow.exceptions.AirflowException: Bash command failed. The command returned a non-zero exit code 1.
[2024-04-09T09:16:34.563+0000] {taskinstance.py:1205} INFO - Marking task as FAILED. dag_id=dag_1, task_id=create_our_works_works_txt_file, execution_date=20240409T090554, start_date=20240409T091633, end_date=20240409T091634
[2024-04-09T09:16:34.620+0000] {standard_task_runner.py:110} ERROR - Failed to execute job 19 for task create_our_works_works_txt_file (Bash command failed. The command returned a non-zero exit code 1.; 1103)
[2024-04-09T09:16:34.687+0000] {local_task_job_runner.py:240} INFO - Task exited with return code 1
[2024-04-09T09:16:34.804+0000] {taskinstance.py:3482} INFO - 0 downstream tasks scheduled from follow-on schedule check
[2024-04-09T09:16:34.846+0000] {local_task_job_runner.py:222} INFO - ::endgroup::
