[2024-04-09T20:09:45.491+0000] {local_task_job_runner.py:120} INFO - ::group::Pre task execution logs
[2024-04-09T20:09:45.900+0000] {taskinstance.py:2073} INFO - Dependencies all met for dep_context=non-requeueable deps ti=<TaskInstance: fruits_dag.get_fruit_data scheduled__2023-04-29T00:00:00+00:00 [queued]>
[2024-04-09T20:09:46.060+0000] {taskinstance.py:2073} INFO - Dependencies all met for dep_context=requeueable deps ti=<TaskInstance: fruits_dag.get_fruit_data scheduled__2023-04-29T00:00:00+00:00 [queued]>
[2024-04-09T20:09:46.069+0000] {taskinstance.py:2303} INFO - Starting attempt 1 of 2
[2024-04-09T20:09:46.619+0000] {taskinstance.py:2327} INFO - Executing <Task(PythonOperator): get_fruit_data> on 2023-04-29 00:00:00+00:00
[2024-04-09T20:09:46.710+0000] {warnings.py:110} WARNING - /home/***/.local/lib/python3.12/site-packages/***/task/task_runner/standard_task_runner.py:61: DeprecationWarning: This process (pid=892) is multi-threaded, use of fork() may lead to deadlocks in the child.
  pid = os.fork()

[2024-04-09T20:09:46.714+0000] {standard_task_runner.py:63} INFO - Started process 902 to run task
[2024-04-09T20:09:46.711+0000] {standard_task_runner.py:90} INFO - Running: ['***', 'tasks', 'run', 'fruits_dag', 'get_fruit_data', 'scheduled__2023-04-29T00:00:00+00:00', '--job-id', '578', '--raw', '--subdir', 'DAGS_FOLDER/fruit_table_dag.py', '--cfg-path', '/tmp/tmpqdat83b5']
[2024-04-09T20:09:46.754+0000] {standard_task_runner.py:91} INFO - Job 578: Subtask get_fruit_data
[2024-04-09T20:09:47.067+0000] {task_command.py:426} INFO - Running <TaskInstance: fruits_dag.get_fruit_data scheduled__2023-04-29T00:00:00+00:00 [running]> on host a89a4f7de6ef
[2024-04-09T20:09:47.577+0000] {taskinstance.py:2644} INFO - Exporting env vars: AIRFLOW_CTX_DAG_OWNER='***' AIRFLOW_CTX_DAG_ID='fruits_dag' AIRFLOW_CTX_TASK_ID='get_fruit_data' AIRFLOW_CTX_EXECUTION_DATE='2023-04-29T00:00:00+00:00' AIRFLOW_CTX_TRY_NUMBER='1' AIRFLOW_CTX_DAG_RUN_ID='scheduled__2023-04-29T00:00:00+00:00'
[2024-04-09T20:09:47.589+0000] {taskinstance.py:430} INFO - ::endgroup::
[2024-04-09T20:09:49.047+0000] {python.py:237} INFO - Done. Returned value was: [{'name': 'Strawberry', 'id': 3, 'family': 'Rosaceae', 'order': 'Rosales', 'genus': 'Fragaria', 'nutritions': {'calories': 29, 'fat': 0.4, 'sugar': 5.4, 'carbohydrates': 5.5, 'protein': 0.8}}, {'name': 'Pear', 'id': 4, 'family': 'Rosaceae', 'order': 'Rosales', 'genus': 'Pyrus', 'nutritions': {'calories': 57, 'fat': 0.1, 'sugar': 10.0, 'carbohydrates': 15.0, 'protein': 0.4}}, {'name': 'Blackberry', 'id': 64, 'family': 'Rosaceae', 'order': 'Rosales', 'genus': 'Rubus', 'nutritions': {'calories': 40, 'fat': 0.4, 'sugar': 4.5, 'carbohydrates': 9.0, 'protein': 1.3}}, {'name': 'Plum', 'id': 71, 'family': 'Rosaceae', 'order': 'Rosales', 'genus': 'Prunus', 'nutritions': {'calories': 46, 'fat': 0.28, 'sugar': 9.92, 'carbohydrates': 11.4, 'protein': 0.7}}, {'name': 'GreenApple', 'id': 72, 'family': 'Rosaceae', 'order': 'Rosales', 'genus': 'Malus', 'nutritions': {'calories': 21, 'fat': 0.1, 'sugar': 6.4, 'carbohydrates': 3.1, 'protein': 0.4}}, {'name': 'Raspberry', 'id': 23, 'family': 'Rosaceae', 'order': 'Rosales', 'genus': 'Rubus', 'nutritions': {'calories': 53, 'fat': 0.7, 'sugar': 4.4, 'carbohydrates': 12.0, 'protein': 1.2}}, {'name': 'Blueberry', 'id': 33, 'family': 'Rosaceae', 'order': 'Rosales', 'genus': 'Fragaria', 'nutritions': {'calories': 29, 'fat': 0.4, 'sugar': 5.4, 'carbohydrates': 5.5, 'protein': 0.0}}, {'name': 'Apple', 'id': 6, 'family': 'Rosaceae', 'order': 'Rosales', 'genus': 'Malus', 'nutritions': {'calories': 52, 'fat': 0.4, 'sugar': 10.3, 'carbohydrates': 11.4, 'protein': 0.3}}, {'name': 'Apricot', 'id': 35, 'family': 'Rosaceae', 'order': 'Rosales', 'genus': 'Prunus', 'nutritions': {'calories': 15, 'fat': 0.1, 'sugar': 3.2, 'carbohydrates': 3.9, 'protein': 0.5}}, {'name': 'Cherry', 'id': 9, 'family': 'Rosaceae', 'order': 'Rosales', 'genus': 'Prunus', 'nutritions': {'calories': 50, 'fat': 0.3, 'sugar': 8.0, 'carbohydrates': 12.0, 'protein': 1.0}}, {'name': 'Peach', 'id': 86, 'family': 'Rosaceae', 'order': 'Rosales', 'genus': 'Prunus', 'nutritions': {'calories': 39, 'fat': 0.25, 'sugar': 8.4, 'carbohydrates': 9.5, 'protein': 0.9}}]
[2024-04-09T20:09:49.070+0000] {taskinstance.py:441} INFO - ::group::Post task execution logs
[2024-04-09T20:09:59.544+0000] {taskinstance.py:2890} ERROR - Task failed with exception
Traceback (most recent call last):
  File "/home/airflow/.local/lib/python3.12/site-packages/sqlalchemy/engine/base.py", line 3371, in _wrap_pool_connect
    return fn()
           ^^^^
  File "/home/airflow/.local/lib/python3.12/site-packages/sqlalchemy/pool/base.py", line 327, in connect
    return _ConnectionFairy._checkout(self)
           ^^^^^^^^^^^^^^^^^^^^^^^^^^^^^^^^
  File "/home/airflow/.local/lib/python3.12/site-packages/sqlalchemy/pool/base.py", line 894, in _checkout
    fairy = _ConnectionRecord.checkout(pool)
            ^^^^^^^^^^^^^^^^^^^^^^^^^^^^^^^^
  File "/home/airflow/.local/lib/python3.12/site-packages/sqlalchemy/pool/base.py", line 493, in checkout
    rec = pool._do_get()
          ^^^^^^^^^^^^^^
  File "/home/airflow/.local/lib/python3.12/site-packages/sqlalchemy/pool/impl.py", line 256, in _do_get
    return self._create_connection()
           ^^^^^^^^^^^^^^^^^^^^^^^^^
  File "/home/airflow/.local/lib/python3.12/site-packages/sqlalchemy/pool/base.py", line 273, in _create_connection
    return _ConnectionRecord(self)
           ^^^^^^^^^^^^^^^^^^^^^^^
  File "/home/airflow/.local/lib/python3.12/site-packages/sqlalchemy/pool/base.py", line 388, in __init__
    self.__connect()
  File "/home/airflow/.local/lib/python3.12/site-packages/sqlalchemy/pool/base.py", line 690, in __connect
    with util.safe_reraise():
  File "/home/airflow/.local/lib/python3.12/site-packages/sqlalchemy/util/langhelpers.py", line 70, in __exit__
    compat.raise_(
  File "/home/airflow/.local/lib/python3.12/site-packages/sqlalchemy/util/compat.py", line 211, in raise_
    raise exception
  File "/home/airflow/.local/lib/python3.12/site-packages/sqlalchemy/pool/base.py", line 686, in __connect
    self.dbapi_connection = connection = pool._invoke_creator(self)
                                         ^^^^^^^^^^^^^^^^^^^^^^^^^^
  File "/home/airflow/.local/lib/python3.12/site-packages/sqlalchemy/engine/create.py", line 574, in connect
    return dialect.connect(*cargs, **cparams)
           ^^^^^^^^^^^^^^^^^^^^^^^^^^^^^^^^^^
  File "/home/airflow/.local/lib/python3.12/site-packages/sqlalchemy/engine/default.py", line 598, in connect
    return self.dbapi.connect(*cargs, **cparams)
           ^^^^^^^^^^^^^^^^^^^^^^^^^^^^^^^^^^^^^
  File "/home/airflow/.local/lib/python3.12/site-packages/psycopg2/__init__.py", line 122, in connect
    conn = _connect(dsn, connection_factory=connection_factory, **kwasync)
           ^^^^^^^^^^^^^^^^^^^^^^^^^^^^^^^^^^^^^^^^^^^^^^^^^^^^^^^^^^^^^^^
psycopg2.OperationalError: could not translate host name "postgres" to address: Temporary failure in name resolution


The above exception was the direct cause of the following exception:

Traceback (most recent call last):
  File "/home/airflow/.local/lib/python3.12/site-packages/airflow/models/taskinstance.py", line 486, in _execute_task
    task_instance.xcom_push(key=XCOM_RETURN_KEY, value=xcom_value, session=session)
  File "/home/airflow/.local/lib/python3.12/site-packages/airflow/utils/session.py", line 76, in wrapper
    return func(*args, **kwargs)
           ^^^^^^^^^^^^^^^^^^^^^
  File "/home/airflow/.local/lib/python3.12/site-packages/airflow/models/taskinstance.py", line 3182, in xcom_push
    XCom.set(
  File "/home/airflow/.local/lib/python3.12/site-packages/airflow/utils/session.py", line 76, in wrapper
    return func(*args, **kwargs)
           ^^^^^^^^^^^^^^^^^^^^^
  File "/home/airflow/.local/lib/python3.12/site-packages/airflow/models/xcom.py", line 222, in set
    dag_run_id = session.query(DagRun.id).filter_by(dag_id=dag_id, run_id=run_id).scalar()
                 ^^^^^^^^^^^^^^^^^^^^^^^^^^^^^^^^^^^^^^^^^^^^^^^^^^^^^^^^^^^^^^^^^^^^^^^^^
  File "/home/airflow/.local/lib/python3.12/site-packages/sqlalchemy/orm/query.py", line 2893, in scalar
    ret = self.one()
          ^^^^^^^^^^
  File "/home/airflow/.local/lib/python3.12/site-packages/sqlalchemy/orm/query.py", line 2870, in one
    return self._iter().one()
           ^^^^^^^^^^^^
  File "/home/airflow/.local/lib/python3.12/site-packages/sqlalchemy/orm/query.py", line 2916, in _iter
    result = self.session.execute(
             ^^^^^^^^^^^^^^^^^^^^^
  File "/home/airflow/.local/lib/python3.12/site-packages/sqlalchemy/orm/session.py", line 1716, in execute
    conn = self._connection_for_bind(bind)
           ^^^^^^^^^^^^^^^^^^^^^^^^^^^^^^^
  File "/home/airflow/.local/lib/python3.12/site-packages/sqlalchemy/orm/session.py", line 1555, in _connection_for_bind
    return self._transaction._connection_for_bind(
           ^^^^^^^^^^^^^^^^^^^^^^^^^^^^^^^^^^^^^^^
  File "/home/airflow/.local/lib/python3.12/site-packages/sqlalchemy/orm/session.py", line 750, in _connection_for_bind
    conn = bind.connect()
           ^^^^^^^^^^^^^^
  File "/home/airflow/.local/lib/python3.12/site-packages/sqlalchemy/future/engine.py", line 412, in connect
    return super(Engine, self).connect()
           ^^^^^^^^^^^^^^^^^^^^^^^^^^^^^
  File "/home/airflow/.local/lib/python3.12/site-packages/sqlalchemy/engine/base.py", line 3325, in connect
    return self._connection_cls(self, close_with_result=close_with_result)
           ^^^^^^^^^^^^^^^^^^^^^^^^^^^^^^^^^^^^^^^^^^^^^^^^^^^^^^^^^^^^^^^
  File "/home/airflow/.local/lib/python3.12/site-packages/sqlalchemy/engine/base.py", line 96, in __init__
    else engine.raw_connection()
         ^^^^^^^^^^^^^^^^^^^^^^^
  File "/home/airflow/.local/lib/python3.12/site-packages/sqlalchemy/engine/base.py", line 3404, in raw_connection
    return self._wrap_pool_connect(self.pool.connect, _connection)
           ^^^^^^^^^^^^^^^^^^^^^^^^^^^^^^^^^^^^^^^^^^^^^^^^^^^^^^^
  File "/home/airflow/.local/lib/python3.12/site-packages/sqlalchemy/engine/base.py", line 3374, in _wrap_pool_connect
    Connection._handle_dbapi_exception_noconnection(
  File "/home/airflow/.local/lib/python3.12/site-packages/sqlalchemy/engine/base.py", line 2208, in _handle_dbapi_exception_noconnection
    util.raise_(
  File "/home/airflow/.local/lib/python3.12/site-packages/sqlalchemy/util/compat.py", line 211, in raise_
    raise exception
  File "/home/airflow/.local/lib/python3.12/site-packages/sqlalchemy/engine/base.py", line 3371, in _wrap_pool_connect
    return fn()
           ^^^^
  File "/home/airflow/.local/lib/python3.12/site-packages/sqlalchemy/pool/base.py", line 327, in connect
    return _ConnectionFairy._checkout(self)
           ^^^^^^^^^^^^^^^^^^^^^^^^^^^^^^^^
  File "/home/airflow/.local/lib/python3.12/site-packages/sqlalchemy/pool/base.py", line 894, in _checkout
    fairy = _ConnectionRecord.checkout(pool)
            ^^^^^^^^^^^^^^^^^^^^^^^^^^^^^^^^
  File "/home/airflow/.local/lib/python3.12/site-packages/sqlalchemy/pool/base.py", line 493, in checkout
    rec = pool._do_get()
          ^^^^^^^^^^^^^^
  File "/home/airflow/.local/lib/python3.12/site-packages/sqlalchemy/pool/impl.py", line 256, in _do_get
    return self._create_connection()
           ^^^^^^^^^^^^^^^^^^^^^^^^^
  File "/home/airflow/.local/lib/python3.12/site-packages/sqlalchemy/pool/base.py", line 273, in _create_connection
    return _ConnectionRecord(self)
           ^^^^^^^^^^^^^^^^^^^^^^^
  File "/home/airflow/.local/lib/python3.12/site-packages/sqlalchemy/pool/base.py", line 388, in __init__
    self.__connect()
  File "/home/airflow/.local/lib/python3.12/site-packages/sqlalchemy/pool/base.py", line 690, in __connect
    with util.safe_reraise():
  File "/home/airflow/.local/lib/python3.12/site-packages/sqlalchemy/util/langhelpers.py", line 70, in __exit__
    compat.raise_(
  File "/home/airflow/.local/lib/python3.12/site-packages/sqlalchemy/util/compat.py", line 211, in raise_
    raise exception
  File "/home/airflow/.local/lib/python3.12/site-packages/sqlalchemy/pool/base.py", line 686, in __connect
    self.dbapi_connection = connection = pool._invoke_creator(self)
                                         ^^^^^^^^^^^^^^^^^^^^^^^^^^
  File "/home/airflow/.local/lib/python3.12/site-packages/sqlalchemy/engine/create.py", line 574, in connect
    return dialect.connect(*cargs, **cparams)
           ^^^^^^^^^^^^^^^^^^^^^^^^^^^^^^^^^^
  File "/home/airflow/.local/lib/python3.12/site-packages/sqlalchemy/engine/default.py", line 598, in connect
    return self.dbapi.connect(*cargs, **cparams)
           ^^^^^^^^^^^^^^^^^^^^^^^^^^^^^^^^^^^^^
  File "/home/airflow/.local/lib/python3.12/site-packages/psycopg2/__init__.py", line 122, in connect
    conn = _connect(dsn, connection_factory=connection_factory, **kwasync)
           ^^^^^^^^^^^^^^^^^^^^^^^^^^^^^^^^^^^^^^^^^^^^^^^^^^^^^^^^^^^^^^^
sqlalchemy.exc.OperationalError: (psycopg2.OperationalError) could not translate host name "postgres" to address: Temporary failure in name resolution

(Background on this error at: https://sqlalche.me/e/14/e3q8)
[2024-04-09T20:10:13.579+0000] {standard_task_runner.py:110} ERROR - Failed to execute job 578 for task get_fruit_data ((psycopg2.OperationalError) could not translate host name "postgres" to address: Temporary failure in name resolution

(Background on this error at: https://sqlalche.me/e/14/e3q8); 902)
[2024-04-09T20:10:15.329+0000] {local_task_job_runner.py:240} INFO - Task exited with return code 1
[2024-04-09T20:10:15.605+0000] {taskinstance.py:3482} INFO - 0 downstream tasks scheduled from follow-on schedule check
[2024-04-09T20:10:15.658+0000] {local_task_job_runner.py:222} INFO - ::endgroup::
