[2024-04-09T12:45:35.833+0000] {local_task_job_runner.py:120} INFO - ::group::Pre task execution logs
[2024-04-09T12:45:35.865+0000] {taskinstance.py:2073} INFO - Dependencies all met for dep_context=non-requeueable deps ti=<TaskInstance: fakestore_api_dag.write_to_csv scheduled__2024-04-08T00:00:00+00:00 [queued]>
[2024-04-09T12:45:35.881+0000] {taskinstance.py:2073} INFO - Dependencies all met for dep_context=requeueable deps ti=<TaskInstance: fakestore_api_dag.write_to_csv scheduled__2024-04-08T00:00:00+00:00 [queued]>
[2024-04-09T12:45:35.882+0000] {taskinstance.py:2303} INFO - Starting attempt 2 of 4
[2024-04-09T12:45:35.917+0000] {taskinstance.py:2327} INFO - Executing <Task(PythonOperator): write_to_csv> on 2024-04-08 00:00:00+00:00
[2024-04-09T12:45:35.930+0000] {warnings.py:110} WARNING - /home/***/.local/lib/python3.12/site-packages/***/task/task_runner/standard_task_runner.py:61: DeprecationWarning: This process (pid=821) is multi-threaded, use of fork() may lead to deadlocks in the child.
  pid = os.fork()

[2024-04-09T12:45:35.933+0000] {standard_task_runner.py:63} INFO - Started process 823 to run task
[2024-04-09T12:45:35.933+0000] {standard_task_runner.py:90} INFO - Running: ['***', 'tasks', 'run', 'fakestore_api_dag', 'write_to_csv', 'scheduled__2024-04-08T00:00:00+00:00', '--job-id', '25', '--raw', '--subdir', 'DAGS_FOLDER/get_write_data_from_api.py', '--cfg-path', '/tmp/tmpjbue8ftp']
[2024-04-09T12:45:35.938+0000] {standard_task_runner.py:91} INFO - Job 25: Subtask write_to_csv
[2024-04-09T12:45:36.021+0000] {task_command.py:426} INFO - Running <TaskInstance: fakestore_api_dag.write_to_csv scheduled__2024-04-08T00:00:00+00:00 [running]> on host a05b73ef9a4b
[2024-04-09T12:45:36.302+0000] {taskinstance.py:2644} INFO - Exporting env vars: AIRFLOW_CTX_DAG_OWNER='***' AIRFLOW_CTX_DAG_ID='fakestore_api_dag' AIRFLOW_CTX_TASK_ID='write_to_csv' AIRFLOW_CTX_EXECUTION_DATE='2024-04-08T00:00:00+00:00' AIRFLOW_CTX_TRY_NUMBER='2' AIRFLOW_CTX_DAG_RUN_ID='scheduled__2024-04-08T00:00:00+00:00'
[2024-04-09T12:45:36.305+0000] {taskinstance.py:430} INFO - ::endgroup::
[2024-04-09T12:45:37.269+0000] {taskinstance.py:441} INFO - ::group::Post task execution logs
[2024-04-09T12:45:37.271+0000] {taskinstance.py:2890} ERROR - Task failed with exception
Traceback (most recent call last):
  File "/home/airflow/.local/lib/python3.12/site-packages/airflow/models/taskinstance.py", line 465, in _execute_task
    result = _execute_callable(context=context, **execute_callable_kwargs)
             ^^^^^^^^^^^^^^^^^^^^^^^^^^^^^^^^^^^^^^^^^^^^^^^^^^^^^^^^^^^^^
  File "/home/airflow/.local/lib/python3.12/site-packages/airflow/models/taskinstance.py", line 432, in _execute_callable
    return execute_callable(context=context, **execute_callable_kwargs)
           ^^^^^^^^^^^^^^^^^^^^^^^^^^^^^^^^^^^^^^^^^^^^^^^^^^^^^^^^^^^^
  File "/home/airflow/.local/lib/python3.12/site-packages/airflow/models/baseoperator.py", line 400, in wrapper
    return func(self, *args, **kwargs)
           ^^^^^^^^^^^^^^^^^^^^^^^^^^^
  File "/home/airflow/.local/lib/python3.12/site-packages/airflow/operators/python.py", line 235, in execute
    return_value = self.execute_callable()
                   ^^^^^^^^^^^^^^^^^^^^^^^
  File "/home/airflow/.local/lib/python3.12/site-packages/airflow/operators/python.py", line 252, in execute_callable
    return self.python_callable(*self.op_args, **self.op_kwargs)
           ^^^^^^^^^^^^^^^^^^^^^^^^^^^^^^^^^^^^^^^^^^^^^^^^^^^^^
  File "/opt/airflow/dags/get_write_data_from_api.py", line 39, in write_to_csv
    with open("/path/to/output/data.csv", "w", newline="") as csv_file:
         ^^^^^^^^^^^^^^^^^^^^^^^^^^^^^^^^^^^^^^^^^^^^^^^^^
FileNotFoundError: [Errno 2] No such file or directory: '/path/to/output/data.csv'
[2024-04-09T12:45:37.300+0000] {taskinstance.py:1205} INFO - Marking task as UP_FOR_RETRY. dag_id=fakestore_api_dag, task_id=write_to_csv, execution_date=20240408T000000, start_date=20240409T124535, end_date=20240409T124537
[2024-04-09T12:45:37.346+0000] {standard_task_runner.py:110} ERROR - Failed to execute job 25 for task write_to_csv ([Errno 2] No such file or directory: '/path/to/output/data.csv'; 823)
[2024-04-09T12:45:37.420+0000] {local_task_job_runner.py:240} INFO - Task exited with return code 1
[2024-04-09T12:45:37.492+0000] {taskinstance.py:3482} INFO - 0 downstream tasks scheduled from follow-on schedule check
[2024-04-09T12:45:37.519+0000] {local_task_job_runner.py:222} INFO - ::endgroup::
[2024-04-09T13:01:48.905+0000] {local_task_job_runner.py:120} INFO - ::group::Pre task execution logs
[2024-04-09T13:01:49.087+0000] {taskinstance.py:2073} INFO - Dependencies all met for dep_context=non-requeueable deps ti=<TaskInstance: fakestore_api_dag.write_to_csv scheduled__2024-04-08T00:00:00+00:00 [queued]>
[2024-04-09T13:01:49.180+0000] {taskinstance.py:2073} INFO - Dependencies all met for dep_context=requeueable deps ti=<TaskInstance: fakestore_api_dag.write_to_csv scheduled__2024-04-08T00:00:00+00:00 [queued]>
[2024-04-09T13:01:49.183+0000] {taskinstance.py:2303} INFO - Starting attempt 2 of 4
[2024-04-09T13:01:49.365+0000] {taskinstance.py:2327} INFO - Executing <Task(PythonOperator): write_to_csv> on 2024-04-08 00:00:00+00:00
[2024-04-09T13:01:49.402+0000] {warnings.py:110} WARNING - /home/***/.local/lib/python3.12/site-packages/***/task/task_runner/standard_task_runner.py:61: DeprecationWarning: This process (pid=1043) is multi-threaded, use of fork() may lead to deadlocks in the child.
  pid = os.fork()

[2024-04-09T13:01:49.456+0000] {standard_task_runner.py:63} INFO - Started process 1055 to run task
[2024-04-09T13:01:49.492+0000] {standard_task_runner.py:90} INFO - Running: ['***', 'tasks', 'run', 'fakestore_api_dag', 'write_to_csv', 'scheduled__2024-04-08T00:00:00+00:00', '--job-id', '40', '--raw', '--subdir', 'DAGS_FOLDER/get_write_data_from_api.py', '--cfg-path', '/tmp/tmpqf19mwfg']
[2024-04-09T13:01:49.544+0000] {standard_task_runner.py:91} INFO - Job 40: Subtask write_to_csv
[2024-04-09T13:01:50.587+0000] {task_command.py:426} INFO - Running <TaskInstance: fakestore_api_dag.write_to_csv scheduled__2024-04-08T00:00:00+00:00 [running]> on host a05b73ef9a4b
[2024-04-09T13:01:51.982+0000] {taskinstance.py:2644} INFO - Exporting env vars: AIRFLOW_CTX_DAG_OWNER='***' AIRFLOW_CTX_DAG_ID='fakestore_api_dag' AIRFLOW_CTX_TASK_ID='write_to_csv' AIRFLOW_CTX_EXECUTION_DATE='2024-04-08T00:00:00+00:00' AIRFLOW_CTX_TRY_NUMBER='2' AIRFLOW_CTX_DAG_RUN_ID='scheduled__2024-04-08T00:00:00+00:00'
[2024-04-09T13:01:52.001+0000] {taskinstance.py:430} INFO - ::endgroup::
[2024-04-09T13:01:52.113+0000] {get_write_data_from_api.py:51} ERROR - Failed to write to CSV file: [Errno 13] Permission denied: '/path'
[2024-04-09T13:01:52.120+0000] {taskinstance.py:441} INFO - ::group::Post task execution logs
[2024-04-09T13:01:52.181+0000] {taskinstance.py:2890} ERROR - Task failed with exception
Traceback (most recent call last):
  File "/home/airflow/.local/lib/python3.12/site-packages/airflow/models/taskinstance.py", line 465, in _execute_task
    result = _execute_callable(context=context, **execute_callable_kwargs)
             ^^^^^^^^^^^^^^^^^^^^^^^^^^^^^^^^^^^^^^^^^^^^^^^^^^^^^^^^^^^^^
  File "/home/airflow/.local/lib/python3.12/site-packages/airflow/models/taskinstance.py", line 432, in _execute_callable
    return execute_callable(context=context, **execute_callable_kwargs)
           ^^^^^^^^^^^^^^^^^^^^^^^^^^^^^^^^^^^^^^^^^^^^^^^^^^^^^^^^^^^^
  File "/home/airflow/.local/lib/python3.12/site-packages/airflow/models/baseoperator.py", line 400, in wrapper
    return func(self, *args, **kwargs)
           ^^^^^^^^^^^^^^^^^^^^^^^^^^^
  File "/home/airflow/.local/lib/python3.12/site-packages/airflow/operators/python.py", line 235, in execute
    return_value = self.execute_callable()
                   ^^^^^^^^^^^^^^^^^^^^^^^
  File "/home/airflow/.local/lib/python3.12/site-packages/airflow/operators/python.py", line 252, in execute_callable
    return self.python_callable(*self.op_args, **self.op_kwargs)
           ^^^^^^^^^^^^^^^^^^^^^^^^^^^^^^^^^^^^^^^^^^^^^^^^^^^^^
  File "/opt/airflow/dags/get_write_data_from_api.py", line 45, in write_to_csv
    os.makedirs(OUTPUT_DIR, exist_ok=True)  # Membuat direktori output jika belum ada
    ^^^^^^^^^^^^^^^^^^^^^^^^^^^^^^^^^^^^^^
  File "<frozen os>", line 215, in makedirs
  File "<frozen os>", line 215, in makedirs
  File "<frozen os>", line 225, in makedirs
PermissionError: [Errno 13] Permission denied: '/path'
[2024-04-09T13:01:52.221+0000] {taskinstance.py:1205} INFO - Marking task as UP_FOR_RETRY. dag_id=fakestore_api_dag, task_id=write_to_csv, execution_date=20240408T000000, start_date=20240409T130149, end_date=20240409T130152
[2024-04-09T13:01:52.327+0000] {standard_task_runner.py:110} ERROR - Failed to execute job 40 for task write_to_csv ([Errno 13] Permission denied: '/path'; 1055)
[2024-04-09T13:01:52.397+0000] {local_task_job_runner.py:240} INFO - Task exited with return code 1
[2024-04-09T13:01:52.566+0000] {taskinstance.py:3482} INFO - 0 downstream tasks scheduled from follow-on schedule check
[2024-04-09T13:01:52.600+0000] {local_task_job_runner.py:222} INFO - ::endgroup::
