[2024-04-09T19:20:41.456+0000] {task_context_logger.py:104} ERROR - Executor reports task instance <TaskInstance: fruits_dag.create_fruits_table scheduled__2023-03-31T00:00:00+00:00 [queued]> finished (failed) although the task says it's queued. (Info: None) Was the task killed externally?
