[2024-04-09T12:43:31.743+0000] {local_task_job_runner.py:120} INFO - ::group::Pre task execution logs
[2024-04-09T12:43:31.802+0000] {taskinstance.py:2073} INFO - Dependencies all met for dep_context=non-requeueable deps ti=<TaskInstance: fakestore_api_dag.write_to_csv manual__2024-04-09T12:43:19.561224+00:00 [queued]>
[2024-04-09T12:43:31.828+0000] {taskinstance.py:2073} INFO - Dependencies all met for dep_context=requeueable deps ti=<TaskInstance: fakestore_api_dag.write_to_csv manual__2024-04-09T12:43:19.561224+00:00 [queued]>
[2024-04-09T12:43:31.830+0000] {taskinstance.py:2303} INFO - Starting attempt 1 of 4
[2024-04-09T12:43:31.902+0000] {taskinstance.py:2327} INFO - Executing <Task(PythonOperator): write_to_csv> on 2024-04-09 12:43:19.561224+00:00
[2024-04-09T12:43:31.928+0000] {standard_task_runner.py:90} INFO - Running: ['***', 'tasks', 'run', 'fakestore_api_dag', 'write_to_csv', 'manual__2024-04-09T12:43:19.561224+00:00', '--job-id', '24', '--raw', '--subdir', 'DAGS_FOLDER/get_write_data_from_api.py', '--cfg-path', '/tmp/tmpmljd32_p']
[2024-04-09T12:43:31.934+0000] {standard_task_runner.py:91} INFO - Job 24: Subtask write_to_csv
[2024-04-09T12:43:31.934+0000] {warnings.py:110} WARNING - /home/***/.local/lib/python3.12/site-packages/***/task/task_runner/standard_task_runner.py:61: DeprecationWarning: This process (pid=797) is multi-threaded, use of fork() may lead to deadlocks in the child.
  pid = os.fork()

[2024-04-09T12:43:31.938+0000] {standard_task_runner.py:63} INFO - Started process 799 to run task
[2024-04-09T12:43:32.107+0000] {task_command.py:426} INFO - Running <TaskInstance: fakestore_api_dag.write_to_csv manual__2024-04-09T12:43:19.561224+00:00 [running]> on host a05b73ef9a4b
[2024-04-09T12:43:32.360+0000] {taskinstance.py:2644} INFO - Exporting env vars: AIRFLOW_CTX_DAG_OWNER='***' AIRFLOW_CTX_DAG_ID='fakestore_api_dag' AIRFLOW_CTX_TASK_ID='write_to_csv' AIRFLOW_CTX_EXECUTION_DATE='2024-04-09T12:43:19.561224+00:00' AIRFLOW_CTX_TRY_NUMBER='1' AIRFLOW_CTX_DAG_RUN_ID='manual__2024-04-09T12:43:19.561224+00:00'
[2024-04-09T12:43:32.365+0000] {taskinstance.py:430} INFO - ::endgroup::
[2024-04-09T12:43:33.053+0000] {taskinstance.py:441} INFO - ::group::Post task execution logs
[2024-04-09T12:43:33.055+0000] {taskinstance.py:2890} ERROR - Task failed with exception
Traceback (most recent call last):
  File "/home/airflow/.local/lib/python3.12/site-packages/airflow/models/taskinstance.py", line 465, in _execute_task
    result = _execute_callable(context=context, **execute_callable_kwargs)
             ^^^^^^^^^^^^^^^^^^^^^^^^^^^^^^^^^^^^^^^^^^^^^^^^^^^^^^^^^^^^^
  File "/home/airflow/.local/lib/python3.12/site-packages/airflow/models/taskinstance.py", line 432, in _execute_callable
    return execute_callable(context=context, **execute_callable_kwargs)
           ^^^^^^^^^^^^^^^^^^^^^^^^^^^^^^^^^^^^^^^^^^^^^^^^^^^^^^^^^^^^
  File "/home/airflow/.local/lib/python3.12/site-packages/airflow/models/baseoperator.py", line 400, in wrapper
    return func(self, *args, **kwargs)
           ^^^^^^^^^^^^^^^^^^^^^^^^^^^
  File "/home/airflow/.local/lib/python3.12/site-packages/airflow/operators/python.py", line 235, in execute
    return_value = self.execute_callable()
                   ^^^^^^^^^^^^^^^^^^^^^^^
  File "/home/airflow/.local/lib/python3.12/site-packages/airflow/operators/python.py", line 252, in execute_callable
    return self.python_callable(*self.op_args, **self.op_kwargs)
           ^^^^^^^^^^^^^^^^^^^^^^^^^^^^^^^^^^^^^^^^^^^^^^^^^^^^^
  File "/opt/airflow/dags/get_write_data_from_api.py", line 39, in write_to_csv
    with open("/path/to/output/data.csv", "w", newline="") as csv_file:
         ^^^^^^^^^^^^^^^^^^^^^^^^^^^^^^^^^^^^^^^^^^^^^^^^^
FileNotFoundError: [Errno 2] No such file or directory: '/path/to/output/data.csv'
[2024-04-09T12:43:33.074+0000] {taskinstance.py:1205} INFO - Marking task as UP_FOR_RETRY. dag_id=fakestore_api_dag, task_id=write_to_csv, execution_date=20240409T124319, start_date=20240409T124331, end_date=20240409T124333
[2024-04-09T12:43:33.092+0000] {standard_task_runner.py:110} ERROR - Failed to execute job 24 for task write_to_csv ([Errno 2] No such file or directory: '/path/to/output/data.csv'; 799)
[2024-04-09T12:43:33.119+0000] {local_task_job_runner.py:240} INFO - Task exited with return code 1
[2024-04-09T12:43:33.150+0000] {taskinstance.py:3482} INFO - 0 downstream tasks scheduled from follow-on schedule check
[2024-04-09T12:43:33.152+0000] {local_task_job_runner.py:222} INFO - ::endgroup::
