[2024-04-09T14:29:26.993+0000] {local_task_job_runner.py:120} INFO - ::group::Pre task execution logs
[2024-04-09T14:29:27.124+0000] {taskinstance.py:2073} INFO - Dependencies all met for dep_context=non-requeueable deps ti=<TaskInstance: fakestore_dag.write_to_csv scheduled__2024-04-08T00:00:00+00:00 [queued]>
[2024-04-09T14:29:27.207+0000] {taskinstance.py:2073} INFO - Dependencies all met for dep_context=requeueable deps ti=<TaskInstance: fakestore_dag.write_to_csv scheduled__2024-04-08T00:00:00+00:00 [queued]>
[2024-04-09T14:29:27.212+0000] {taskinstance.py:2303} INFO - Starting attempt 2 of 4
[2024-04-09T14:29:27.337+0000] {taskinstance.py:2327} INFO - Executing <Task(PythonOperator): write_to_csv> on 2024-04-08 00:00:00+00:00
[2024-04-09T14:29:27.362+0000] {standard_task_runner.py:90} INFO - Running: ['***', 'tasks', 'run', 'fakestore_dag', 'write_to_csv', 'scheduled__2024-04-08T00:00:00+00:00', '--job-id', '110', '--raw', '--subdir', 'DAGS_FOLDER/get_write_data_from_api.py', '--cfg-path', '/tmp/tmp0czab_b3']
[2024-04-09T14:29:27.359+0000] {warnings.py:110} WARNING - /home/***/.local/lib/python3.12/site-packages/***/task/task_runner/standard_task_runner.py:61: DeprecationWarning: This process (pid=2249) is multi-threaded, use of fork() may lead to deadlocks in the child.
  pid = os.fork()

[2024-04-09T14:29:27.365+0000] {standard_task_runner.py:91} INFO - Job 110: Subtask write_to_csv
[2024-04-09T14:29:27.366+0000] {standard_task_runner.py:63} INFO - Started process 2256 to run task
[2024-04-09T14:29:27.615+0000] {task_command.py:426} INFO - Running <TaskInstance: fakestore_dag.write_to_csv scheduled__2024-04-08T00:00:00+00:00 [running]> on host a05b73ef9a4b
[2024-04-09T14:29:28.041+0000] {taskinstance.py:2644} INFO - Exporting env vars: AIRFLOW_CTX_DAG_OWNER='***' AIRFLOW_CTX_DAG_ID='fakestore_dag' AIRFLOW_CTX_TASK_ID='write_to_csv' AIRFLOW_CTX_EXECUTION_DATE='2024-04-08T00:00:00+00:00' AIRFLOW_CTX_TRY_NUMBER='2' AIRFLOW_CTX_DAG_RUN_ID='scheduled__2024-04-08T00:00:00+00:00'
[2024-04-09T14:29:28.059+0000] {taskinstance.py:430} INFO - ::endgroup::
[2024-04-09T14:29:28.123+0000] {get_write_data_from_api.py:49} ERROR - Failed to write to CSV file: [Errno 13] Permission denied: '/path'
[2024-04-09T14:29:28.127+0000] {taskinstance.py:441} INFO - ::group::Post task execution logs
[2024-04-09T14:29:28.129+0000] {taskinstance.py:2890} ERROR - Task failed with exception
Traceback (most recent call last):
  File "/home/airflow/.local/lib/python3.12/site-packages/airflow/models/taskinstance.py", line 465, in _execute_task
    result = _execute_callable(context=context, **execute_callable_kwargs)
             ^^^^^^^^^^^^^^^^^^^^^^^^^^^^^^^^^^^^^^^^^^^^^^^^^^^^^^^^^^^^^
  File "/home/airflow/.local/lib/python3.12/site-packages/airflow/models/taskinstance.py", line 432, in _execute_callable
    return execute_callable(context=context, **execute_callable_kwargs)
           ^^^^^^^^^^^^^^^^^^^^^^^^^^^^^^^^^^^^^^^^^^^^^^^^^^^^^^^^^^^^
  File "/home/airflow/.local/lib/python3.12/site-packages/airflow/models/baseoperator.py", line 400, in wrapper
    return func(self, *args, **kwargs)
           ^^^^^^^^^^^^^^^^^^^^^^^^^^^
  File "/home/airflow/.local/lib/python3.12/site-packages/airflow/operators/python.py", line 235, in execute
    return_value = self.execute_callable()
                   ^^^^^^^^^^^^^^^^^^^^^^^
  File "/home/airflow/.local/lib/python3.12/site-packages/airflow/operators/python.py", line 252, in execute_callable
    return self.python_callable(*self.op_args, **self.op_kwargs)
           ^^^^^^^^^^^^^^^^^^^^^^^^^^^^^^^^^^^^^^^^^^^^^^^^^^^^^
  File "/opt/airflow/dags/get_write_data_from_api.py", line 44, in write_to_csv
    os.makedirs(OUTPUT_DIR, exist_ok=True)
  File "<frozen os>", line 215, in makedirs
  File "<frozen os>", line 215, in makedirs
  File "<frozen os>", line 225, in makedirs
PermissionError: [Errno 13] Permission denied: '/path'
[2024-04-09T14:29:28.200+0000] {taskinstance.py:1205} INFO - Marking task as UP_FOR_RETRY. dag_id=fakestore_dag, task_id=write_to_csv, execution_date=20240408T000000, start_date=20240409T142927, end_date=20240409T142928
[2024-04-09T14:29:28.270+0000] {standard_task_runner.py:110} ERROR - Failed to execute job 110 for task write_to_csv ([Errno 13] Permission denied: '/path'; 2256)
[2024-04-09T14:29:28.392+0000] {local_task_job_runner.py:240} INFO - Task exited with return code 1
[2024-04-09T14:29:28.584+0000] {taskinstance.py:3482} INFO - 0 downstream tasks scheduled from follow-on schedule check
[2024-04-09T14:29:28.603+0000] {local_task_job_runner.py:222} INFO - ::endgroup::
