[2024-04-09T18:43:43.330+0000] {task_context_logger.py:104} ERROR - Executor reports task instance <TaskInstance: fruits_dag.insert_fruit_data scheduled__2023-03-05T00:00:00+00:00 [queued]> finished (failed) although the task says it's queued. (Info: None) Was the task killed externally?
